version: '2.2'

services:
  postgis:
    image: cartoview/cartoview-postgis:latest
    restart: unless-stopped
    env_file:
      - ./postgis.env
    volumes:
      - "./pgdata:/var/lib/postgresql"
    ports:
      - "5432:5432"
    expose:
      - "5432"
    networks:
      internal:
      cartoview:
        ipv4_address: 10.5.0.2
  geoserver:
    image: geonode/geoserver:2.9.x-oauth2
    restart: unless-stopped
    depends_on:
      - postgis
    volumes:
      - "./geoserver/data:/geoserver_data/data"
    ports:
      - "8080:8080"
    expose:
      - "8080"
    networks:
      internal:
      cartoview:
        ipv4_address: 10.5.0.3
  cartoview:
    command: bash -c "python server.py"
    restart: unless-stopped
    image: cartoview/cartoview:latest
    depends_on:
      - postgis
      - geoserver
    env_file:
      - ./django.env
    volumes:
      - "./:/code/"
    ports:
      - "8000:8000"
    expose:
      - "8000"
    networks:
      internal:
      cartoview:
        ipv4_address: 10.5.0.4
  nginx:
    image: nginx:alpine
    restart: unless-stopped
    ports:
      - "80:80"
    volumes:
      - ./nginx/nginx.conf:/etc/nginx/nginx.conf
    networks:
      internal:
      cartoview:
        ipv4_address: 10.5.0.5
networks:
  internal:
  cartoview:
    driver: bridge
    ipam:
     config:
       - subnet: 10.5.0.0/16
         gateway: 10.5.0.1